<robot name="onshape">
    <link name="drivetrain_assembly">
        <visual>
            <origin xyz="-0.4572 -0.3048 0" rpy="0 -0 0"/>
            <geometry>
                <mesh filename="package://drivetrain.stl"/>
            </geometry>
            <material name="drivetrain_material">
                <color rgba="0.615686 0.811765 0.929412 1.0"/>
            </material>
        </visual>
        <collision>
            <origin xyz="-0.4572 -0.3048 0" rpy="0 -0 0"/>
            <geometry>
                <mesh filename="package://drivetrain.stl"/>
            </geometry>
            <material name="drivetrain_material">
                <color rgba="0.615686 0.811765 0.929412 1.0"/>
            </material>
        </collision>
        <visual>
            <origin xyz="0.43815 0.28575 0.127" rpy="2.12635e-17 5.12772e-17 -1.5708"/>
            <geometry>
                <mesh filename="package://telescoping_holder.stl"/>
            </geometry>
            <material name="telescoping_holder_material">
                <color rgba="0.647059 0.647059 0.647059 1.0"/>
            </material>
        </visual>
        <collision>
            <origin xyz="0.43815 0.28575 0.127" rpy="2.12635e-17 5.12772e-17 -1.5708"/>
            <geometry>
                <mesh filename="package://telescoping_holder.stl"/>
            </geometry>
            <material name="telescoping_holder_material">
                <color rgba="0.647059 0.647059 0.647059 1.0"/>
            </material>
        </collision>
        <visual>
            <origin xyz="0.43815 -0.28575 0.127" rpy="2.12635e-17 5.12772e-17 1.5708"/>
            <geometry>
                <mesh filename="package://telescoping_holder.stl"/>
            </geometry>
            <material name="telescoping_holder_material">
                <color rgba="0.647059 0.647059 0.647059 1.0"/>
            </material>
        </visual>
        <collision>
            <origin xyz="0.43815 -0.28575 0.127" rpy="2.12635e-17 5.12772e-17 1.5708"/>
            <geometry>
                <mesh filename="package://telescoping_holder.stl"/>
            </geometry>
            <material name="telescoping_holder_material">
                <color rgba="0.647059 0.647059 0.647059 1.0"/>
            </material>
        </collision>
        <inertial>
            <origin xyz="-0.117123 -3.31188e-16 0.205744" rpy="0 0 0"/>
            <mass value="303.881"/>
            <inertia ixx="21.2597" ixy="-3.10862e-15" ixz="8.37918" iyy="36.7853" iyz="1.31839e-15" izz="28.9018"/>
        </inertial>
    </link>

    <link name="telescoping_hooks_assembly">
        <visual>
            <origin xyz="0 0 -0.889" rpy="0 -3.08149e-33 5.45672e-47"/>
            <geometry>
                <mesh filename="package://telescoping_hook.stl"/>
            </geometry>
            <material name="telescoping_hook_material">
                <color rgba="0.615686 0.811765 0.929412 1.0"/>
            </material>
        </visual>
        <collision>
            <origin xyz="0 0 -0.889" rpy="0 -3.08149e-33 5.45672e-47"/>
            <geometry>
                <mesh filename="package://telescoping_hook.stl"/>
            </geometry>
            <material name="telescoping_hook_material">
                <color rgba="0.615686 0.811765 0.929412 1.0"/>
            </material>
        </collision>
        <visual>
            <origin xyz="0 0.5715 -0.889" rpy="0 -3.08149e-33 5.45672e-47"/>
            <geometry>
                <mesh filename="package://telescoping_hook.stl"/>
            </geometry>
            <material name="telescoping_hook_material">
                <color rgba="0.615686 0.811765 0.929412 1.0"/>
            </material>
        </visual>
        <collision>
            <origin xyz="0 0.5715 -0.889" rpy="0 -3.08149e-33 5.45672e-47"/>
            <geometry>
                <mesh filename="package://telescoping_hook.stl"/>
            </geometry>
            <material name="telescoping_hook_material">
                <color rgba="0.615686 0.811765 0.929412 1.0"/>
            </material>
        </collision>
        <inertial>
            <origin xyz="2.13016e-17 0.28575 -0.446524" rpy="0 0 0"/>
            <mass value="1.36123"/>
            <inertia ixx="0.201718" ixy="9.87512e-35" ixz="2.79792e-34" iyy="0.0905698" iyz="2.15922e-17"
                     izz="0.111376"/>
        </inertial>
    </link>

    <link name="passive_hook">
        <visual>
            <origin xyz="-0.0889 -0.03175 -0.00635" rpy="-1.5708 -1.5708 0"/>
            <geometry>
                <box size="0.0127 0.0127 0.0635"/>
            </geometry>
            <material name="telescoping_hook_1_new_material">
                <color rgba="0.615686 0.811765 0.929412 1.0"/>
            </material>
        </visual>
        <collision>
            <origin xyz="-0.0889 -0.03175 -0.00635" rpy="-1.5708 -1.5708 0"/>
            <geometry>
                <box size="0.0127 0.0127 0.0635"/>
            </geometry>
            <material name="telescoping_hook_1_new_material">
                <color rgba="0.615686 0.811765 0.929412 1.0"/>
            </material>
        </collision>
        <visual>
            <origin xyz="-0.04445 -0.06985 -0.00635" rpy="1.02554e-16 -1.5708 0"/>
            <geometry>
                <box size="0.0127 0.0127 0.1016"/>
            </geometry>
            <material name="telescoping_hook_3_new_material">
                <color rgba="0.615686 0.811765 0.929412 1.0"/>
            </material>
        </visual>
        <collision>
            <origin xyz="-0.04445 -0.06985 -0.00635" rpy="1.02554e-16 -1.5708 0"/>
            <geometry>
                <box size="0.0127 0.0127 0.1016"/>
            </geometry>
            <material name="telescoping_hook_3_new_material">
                <color rgba="0.615686 0.811765 0.929412 1.0"/>
            </material>
        </collision>
        <visual>
            <origin xyz="-5.55112e-17 -0.03175 -0.00635" rpy="-1.5708 -1.5708 0"/>
            <geometry>
                <box size="0.0127 0.0127 0.0635"/>
            </geometry>
            <material name="telescoping_hook_1_new_material">
                <color rgba="0.615686 0.811765 0.929412 1.0"/>
            </material>
        </visual>
        <collision>
            <origin xyz="-5.55112e-17 -0.03175 -0.00635" rpy="-1.5708 -1.5708 0"/>
            <geometry>
                <box size="0.0127 0.0127 0.0635"/>
            </geometry>
            <material name="telescoping_hook_1_new_material">
                <color rgba="0.615686 0.811765 0.929412 1.0"/>
            </material>
        </collision>
        <inertial>
            <origin xyz="-0.04445 -0.0486833 -0.00635" rpy="0 0 0"/>
            <mass value="0.0995514"/>
            <inertia ixx="3.83575e-05" ixy="-3.28649e-19" ixz="-1.2053e-21" iyy="0.000167257" iyz="4.77721e-35"
                     izz="0.000202938"/>
        </inertial>
    </link>

    <joint name="activehook1" type="fixed">
        <origin xyz="0 0.561975 2.22045e-16" rpy="-1.5708 -3.08149e-33 3.14159"/>
        <parent link="telescoping_hooks_assembly"/>
        <child link="passive_hook"/>
        <axis xyz="0 0 1"/>
        <limit effort="1" velocity="20"/>
        <joint_properties friction="0.0"/>
    </joint>

    <link name="passive_hook_2">
        <visual>
            <origin xyz="-5.55112e-17 -0.03175 -0.00635" rpy="-1.5708 -1.5708 0"/>
            <geometry>
                <box size="0.0127 0.0127 0.0635"/>
            </geometry>
            <material name="telescoping_hook_1_new_material">
                <color rgba="0.615686 0.811765 0.929412 1.0"/>
            </material>
        </visual>
        <collision>
            <origin xyz="-5.55112e-17 -0.03175 -0.00635" rpy="-1.5708 -1.5708 0"/>
            <geometry>
                <box size="0.0127 0.0127 0.0635"/>
            </geometry>
            <material name="telescoping_hook_1_new_material">
                <color rgba="0.615686 0.811765 0.929412 1.0"/>
            </material>
        </collision>
        <visual>
            <origin xyz="-0.0889 -0.03175 -0.00635" rpy="-1.5708 -1.5708 0"/>
            <geometry>
                <box size="0.0127 0.0127 0.0635"/>
            </geometry>
            <material name="telescoping_hook_1_new_material">
                <color rgba="0.615686 0.811765 0.929412 1.0"/>
            </material>
        </visual>
        <collision>
            <origin xyz="-0.0889 -0.03175 -0.00635" rpy="-1.5708 -1.5708 0"/>
            <geometry>
                <box size="0.0127 0.0127 0.0635"/>
            </geometry>
            <material name="telescoping_hook_1_new_material">
                <color rgba="0.615686 0.811765 0.929412 1.0"/>
            </material>
        </collision>
        <visual>
            <origin xyz="-0.04445 -0.06985 -0.00635" rpy="4.06835e-27 -1.5708 0"/>
            <geometry>
                <box size="0.0127 0.0127 0.1016"/>
            </geometry>
            <material name="telescoping_hook_3_new_material">
                <color rgba="0.615686 0.811765 0.929412 1.0"/>
            </material>
        </visual>
        <collision>
            <origin xyz="-0.04445 -0.06985 -0.00635" rpy="4.06835e-27 -1.5708 0"/>
            <geometry>
                <box size="0.0127 0.0127 0.1016"/>
            </geometry>
            <material name="telescoping_hook_3_new_material">
                <color rgba="0.615686 0.811765 0.929412 1.0"/>
            </material>
        </collision>
        <inertial>
            <origin xyz="-0.04445 -0.0486833 -0.00635" rpy="0 0 0"/>
            <mass value="0.0995514"/>
            <inertia ixx="3.83575e-05" ixy="4.33475e-19" ixz="-4.38732e-22" iyy="0.000167257" iyz="-5.41331e-20"
                     izz="0.000202938"/>
        </inertial>
    </link>

    <joint name="activehook2" type="fixed">
        <origin xyz="-5.55112e-17 -0.009525 4.44089e-16" rpy="-1.5708 -8.51976e-28 -3.14159"/>
        <parent link="telescoping_hooks_assembly"/>
        <child link="passive_hook_2"/>
        <axis xyz="0 0 1"/>
        <limit effort="1" velocity="20"/>
        <joint_properties friction="0.0"/>
    </joint>

    <joint name="telescope" type="prismatic">
        <origin xyz="0.43815 -0.28575 1.016" rpy="-5.12772e-17 2.12635e-17 1.03467e-30"/>
        <parent link="drivetrain_assembly"/>
        <child link="telescoping_hooks_assembly"/>
        <axis xyz="0 0 1"/>
        <limit effort="1" velocity="20"/>
        <joint_properties friction="0.0"/>
    </joint>

    <link name="passive_hook_3">
        <visual>
            <origin xyz="0.04445 -0.06985 -0.00635" rpy="-3.33067e-16 -1.5708 0"/>
            <geometry>
                <box size="0.0127 0.0127 0.1016"/>
            </geometry>
            <material name="telescoping_hook_3_new_material">
                <color rgba="0.615686 0.811765 0.929412 1.0"/>
            </material>
        </visual>
        <collision>
            <origin xyz="0.04445 -0.06985 -0.00635" rpy="-3.33067e-16 -1.5708 0"/>
            <geometry>
                <box size="0.0127 0.0127 0.1016"/>
            </geometry>
            <material name="telescoping_hook_3_new_material">
                <color rgba="0.615686 0.811765 0.929412 1.0"/>
            </material>
        </collision>
        <visual>
            <origin xyz="1.11022e-16 -0.03175 -0.00635" rpy="-1.5708 -1.5708 0"/>
            <geometry>
                <box size="0.0127 0.0127 0.0635"/>
            </geometry>
            <material name="telescoping_hook_1_new_material">
                <color rgba="0.615686 0.811765 0.929412 1.0"/>
            </material>
        </visual>
        <collision>
            <origin xyz="1.11022e-16 -0.03175 -0.00635" rpy="-1.5708 -1.5708 0"/>
            <geometry>
                <box size="0.0127 0.0127 0.0635"/>
            </geometry>
            <material name="telescoping_hook_1_new_material">
                <color rgba="0.615686 0.811765 0.929412 1.0"/>
            </material>
        </collision>
        <visual>
            <origin xyz="0.0889 -0.03175 -0.00635" rpy="-1.5708 -1.5708 0"/>
            <geometry>
                <box size="0.0127 0.0127 0.0635"/>
            </geometry>
            <material name="telescoping_hook_1_new_material">
                <color rgba="0.615686 0.811765 0.929412 1.0"/>
            </material>
        </visual>
        <collision>
            <origin xyz="0.0889 -0.03175 -0.00635" rpy="-1.5708 -1.5708 0"/>
            <geometry>
                <box size="0.0127 0.0127 0.0635"/>
            </geometry>
            <material name="telescoping_hook_1_new_material">
                <color rgba="0.615686 0.811765 0.929412 1.0"/>
            </material>
        </collision>
        <inertial>
            <origin xyz="0.04445 -0.0486833 -0.00635" rpy="0 0 0"/>
            <mass value="0.0995514"/>
            <inertia ixx="3.83575e-05" ixy="2.47334e-19" ixz="1.30441e-19" iyy="0.000167257" iyz="-4.23313e-20"
                     izz="0.000202938"/>
        </inertial>
    </link>

    <joint name="passivehook1" type="revolute">
        <origin xyz="0.43815 0.2667 1.016" rpy="-1.5708 1.4527e-16 -3.33067e-16"/>
        <parent link="drivetrain_assembly"/>
        <child link="passive_hook_3"/>
        <axis xyz="0 0 1"/>
        <limit effort="1" velocity="20"/>
        <joint_properties friction="0.0"/>
    </joint>

    <link name="passive_hook_4">
        <visual>
            <origin xyz="0.04445 -0.06985 -0.00635" rpy="-0 -1.5708 0"/>
            <geometry>
                <box size="0.0127 0.0127 0.1016"/>
            </geometry>
            <material name="telescoping_hook_3_new_material">
                <color rgba="0.615686 0.811765 0.929412 1.0"/>
            </material>
        </visual>
        <collision>
            <origin xyz="0.04445 -0.06985 -0.00635" rpy="-0 -1.5708 0"/>
            <geometry>
                <box size="0.0127 0.0127 0.1016"/>
            </geometry>
            <material name="telescoping_hook_3_new_material">
                <color rgba="0.615686 0.811765 0.929412 1.0"/>
            </material>
        </collision>
        <visual>
            <origin xyz="0.0889 -0.03175 -0.00635" rpy="-1.5708 -1.5708 0"/>
            <geometry>
                <box size="0.0127 0.0127 0.0635"/>
            </geometry>
            <material name="telescoping_hook_1_new_material">
                <color rgba="0.615686 0.811765 0.929412 1.0"/>
            </material>
        </visual>
        <collision>
            <origin xyz="0.0889 -0.03175 -0.00635" rpy="-1.5708 -1.5708 0"/>
            <geometry>
                <box size="0.0127 0.0127 0.0635"/>
            </geometry>
            <material name="telescoping_hook_1_new_material">
                <color rgba="0.615686 0.811765 0.929412 1.0"/>
            </material>
        </collision>
        <visual>
            <origin xyz="5.55112e-17 -0.03175 -0.00635" rpy="-1.5708 -1.5708 0"/>
            <geometry>
                <box size="0.0127 0.0127 0.0635"/>
            </geometry>
            <material name="telescoping_hook_1_new_material">
                <color rgba="0.615686 0.811765 0.929412 1.0"/>
            </material>
        </visual>
        <collision>
            <origin xyz="5.55112e-17 -0.03175 -0.00635" rpy="-1.5708 -1.5708 0"/>
            <geometry>
                <box size="0.0127 0.0127 0.0635"/>
            </geometry>
            <material name="telescoping_hook_1_new_material">
                <color rgba="0.615686 0.811765 0.929412 1.0"/>
            </material>
        </collision>
        <inertial>
            <origin xyz="0.04445 -0.0486833 -0.00635" rpy="0 0 0"/>
            <mass value="0.0995514"/>
            <inertia ixx="3.83575e-05" ixy="-4.91279e-19" ixz="-1.41452e-19" iyy="0.000167257" iyz="5.19873e-20"
                     izz="0.000202938"/>
        </inertial>
    </link>

    <joint name="passivehook2" type="revolute">
        <origin xyz="0.43815 -0.3048 1.016" rpy="-1.5708 2.12635e-17 -9.10616e-17"/>
        <parent link="drivetrain_assembly"/>
        <child link="passive_hook_4"/>
        <axis xyz="0 0 1"/>
        <limit effort="1" velocity="20"/>
        <joint_properties friction="0.0"/>
    </joint>


</robot>
